<?xml version="1.0"?>
<robot name="my_sim_robot">

  <link name="base_link">
    <visual>
      <geometry>
        <box size="0.5 0.3 0.1"/>
      </geometry>
      <material name="blue">
        <color rgba="0 0 1 1"/>
      </material>
    </visual>
    <collision>
      <geometry>
        <box size="0.5 0.3 0.1"/>
      </geometry>
    </collision>
    <inertial>
      <mass value="1.0"/>
      <inertia ixx="0.01" ixy="0" ixz="0" iyy="0.01" iyz="0" izz="0.01"/>
    </inertial>
  </link>

  <material name="black">
    <color rgba="0 0 0 1"/>
  </material>

  <link name="wheel_fl">
    <visual>
      <geometry>
        <cylinder length="0.05" radius="0.1"/>
      </geometry>
      <material name="black"/>
    </visual>
    <collision>
      <geometry>
        <cylinder length="0.05" radius="0.1"/>
      </geometry>
    </collision>
    <inertial>
      <mass value="0.2"/>
      <inertia ixx="0.001" ixy="0" ixz="0" iyy="0.001" iyz="0" izz="0.001"/>
    </inertial>
  </link>

  <joint name="wheel_fl_joint" type="continuous">
    <parent link="base_link"/>
    <child link="wheel_fl"/>
    <origin xyz="0.2 0.175 0" rpy="1.5708 0 0"/>
    <axis xyz="0 0 1"/>
  </joint>

  <transmission name="wheel_fl_trans">
    <type>transmission_interface/SimpleTransmission</type>
    <joint name="wheel_fl_joint">
      <hardwareInterface>hardware_interface/VelocityJointInterface</hardwareInterface>
    </joint>
    <actuator name="wheel_fl_motor">
      <mechanicalReduction>1</mechanicalReduction>
    </actuator>
  </transmission>

  <gazebo reference="wheel_fl">
    <mu1>1.0</mu1>
    <mu2>1.0</mu2>
    <material>Gazebo/Black</material>
  </gazebo>

  <link name="wheel_fr">
    <visual>
      <geometry>
        <cylinder length="0.05" radius="0.1"/>
      </geometry>
      <material name="black"/>
    </visual>
    <collision>
      <geometry>
        <cylinder length="0.05" radius="0.1"/>
      </geometry>
    </collision>
    <inertial>
      <mass value="0.2"/>
      <inertia ixx="0.001" ixy="0" ixz="0" iyy="0.001" iyz="0" izz="0.001"/>
    </inertial>
  </link>

  <joint name="wheel_fr_joint" type="continuous">
    <parent link="base_link"/>
    <child link="wheel_fr"/>
    <origin xyz="0.2 -0.175 0" rpy="1.5708 0 0"/>
    <axis xyz="0 0 1"/>
  </joint>

  <transmission name="wheel_fr_trans">
    <type>transmission_interface/SimpleTransmission</type>
    <joint name="wheel_fr_joint">
      <hardwareInterface>hardware_interface/VelocityJointInterface</hardwareInterface>
    </joint>
    <actuator name="wheel_fr_motor">
      <mechanicalReduction>1</mechanicalReduction>
    </actuator>
  </transmission>

  <gazebo reference="wheel_fr">
    <mu1>1.0</mu1>
    <mu2>1.0</mu2>
    <material>Gazebo/Black</material>
  </gazebo>

  <link name="wheel_rl">
    <visual>
      <geometry>
        <cylinder length="0.05" radius="0.1"/>
      </geometry>
      <material name="black"/>
    </visual>
    <collision>
      <geometry>
        <cylinder length="0.05" radius="0.1"/>
      </geometry>
    </collision>
    <inertial>
      <mass value="0.2"/>
      <inertia ixx="0.001" ixy="0" ixz="0" iyy="0.001" iyz="0" izz="0.001"/>
    </inertial>
  </link>

  <joint name="wheel_rl_joint" type="continuous">
    <parent link="base_link"/>
    <child link="wheel_rl"/>
    <origin xyz="-0.2 0.175 0" rpy="1.5708 0 0"/>
    <axis xyz="0 0 1"/>
  </joint>

  <transmission name="wheel_rl_trans">
    <type>transmission_interface/SimpleTransmission</type>
    <joint name="wheel_rl_joint">
      <hardwareInterface>hardware_interface/VelocityJointInterface</hardwareInterface>
    </joint>
    <actuator name="wheel_rl_motor">
      <mechanicalReduction>1</mechanicalReduction>
    </actuator>
  </transmission>

  <gazebo reference="wheel_rl">
    <mu1>1.0</mu1>
    <mu2>1.0</mu2>
    <material>Gazebo/Black</material>
  </gazebo>

  <link name="wheel_rr">
    <visual>
      <geometry>
        <cylinder length="0.05" radius="0.1"/>
      </geometry>
      <material name="black"/>
    </visual>
    <collision>
      <geometry>
        <cylinder length="0.05" radius="0.1"/>
      </geometry>
    </collision>
    <inertial>
      <mass value="0.2"/>
      <inertia ixx="0.001" ixy="0" ixz="0" iyy="0.001" iyz="0" izz="0.001"/>
    </inertial>
  </link>

  <joint name="wheel_rr_joint" type="continuous">
    <parent link="base_link"/>
    <child link="wheel_rr"/>
    <origin xyz="-0.2 -0.175 0" rpy="1.5708 0 0"/>
    <axis xyz="0 0 1"/>
  </joint>

  <transmission name="wheel_rr_trans">
    <type>transmission_interface/SimpleTransmission</type>
    <joint name="wheel_rr_joint">
      <hardwareInterface>hardware_interface/VelocityJointInterface</hardwareInterface>
    </joint>
    <actuator name="wheel_rr_motor">
      <mechanicalReduction>1</mechanicalReduction>
    </actuator>
  </transmission>

  <gazebo reference="wheel_rr">
    <mu1>1.0</mu1>
    <mu2>1.0</mu2>
    <material>Gazebo/Black</material>
  </gazebo>

  <gazebo>
    <plugin name="skid_steer_drive_controller" filename="libgazebo_ros_skid_steer_drive.so">
      <updateRate>100.0</updateRate>
      <robotNamespace>/</robotNamespace>
      <leftFrontJoint>wheel_fl_joint</leftFrontJoint>
      <rightFrontJoint>wheel_fr_joint</rightFrontJoint>
      <leftRearJoint>wheel_rl_joint</leftRearJoint>
      <rightRearJoint>wheel_rr_joint</rightRearJoint>
      
      <wheelSeparation>0.35</wheelSeparation> <wheelDiameter>0.2</wheelDiameter>      <torque>20</torque>
      <commandTopic>cmd_vel</commandTopic>
      <odometryTopic>odom</odometryTopic>
      <odometryFrame>odom</odometryFrame>
      <robotBaseFrame>base_link</robotBaseFrame>
      <publishWheelTF>true</publishWheelTF>
      <publishOdomTF>true</publishOdomTF>
    </plugin>
  </gazebo>

</robot>